Workbook

Sheet Clean
A1: Number | B1: District Name in Arabic | C1: District Name in English | D1: Region | E1: New Region | F1: name_en | G1: Done (Yes or No) | H1: Need to be checked (Yes or No) | I1: Empty based on google map (Yes or No) | J1: Comments
A2: 50 | B2: الراية | C2: Al Rayah | D2: East | E2: =VLOOKUP(C2, Sheet2!C:D, 2, FALSE) -> East | F2: Al Rayah | G2: No | H2: No | I2: Yes
A3: 51 | B3: البساتين | C3: Al Basatin | D3: East | E3: =VLOOKUP(C3, Sheet2!C:D, 2, FALSE) -> East | F3: Al Basatin | G3: No | H3: No | I3: Yes | J3: Includes Dhahyat Al Fursan
A4: 52 | B4: الشعلة | C4: Al Sholah | D4: East | E4: =VLOOKUP(C4, Sheet2!C:D, 2, FALSE) -> East | F4: Al Sholah | G4: No | H4: No | I4: Yes
A5: 53 | B5: الزاهر | C5: Al Zaher | D5: East | E5: =VLOOKUP(C5, Sheet2!C:D, 2, FALSE) -> East | F5: Al Zaher | G5: No | H5: No | I5: Yes
A6: 54 | B6: الزهور | C6: Al Zahour | D6: East | E6: =VLOOKUP(C6, Sheet2!C:D, 2, FALSE) -> East | F6: Al Zahour | G6: No | H6: No | I6: Yes
A7: 55 | B7: المجد | C7: Al Majd | D7: East | E7: =VLOOKUP(C7, Sheet2!C:D, 2, FALSE) -> East | F7: Al Majd | G7: No | H7: No | I7: Yes
A8: 56 | B8: الرسالة | C8: Al Risalah | D8: East | E8: =VLOOKUP(C8, Sheet2!C:D, 2, FALSE) -> East | F8: Al Risalah | G8: No | H8: No | I8: Yes
A9: 57 | B9: العلا | C9: Al Ula | D9: East | E9: =VLOOKUP(C9, Sheet2!C:D, 2, FALSE) -> East | F9: Al Ula | G9: No | H9: No | I9: Yes
A10: 58 | B10: الدانة | C10: Al Danah | D10: East | E10: =VLOOKUP(C10, Sheet2!C:D, 2, FALSE) -> East | F10: Al Danah | G10: No | H10: No | I10: Yes
A11: 59 | B11: النخبة | C11: Al Nakhbah | D11: East | E11: =VLOOKUP(C11, Sheet2!C:D, 2, FALSE) -> East | F11: Al Nakhbah | G11: No | H11: No | I11: Yes
A12: 60 | B12: البشائر | C12: Al Bashaer | D12: East | E12: =VLOOKUP(C12, Sheet2!C:D, 2, FALSE) -> East | F12: Al Bashaer | G12: No | H12: No | I12: Yes
A13: 61 | B13: المشرق | C13: Al Mashriq | D13: East | E13: =VLOOKUP(C13, Sheet2!C:D, 2, FALSE) -> East | F13: Al Mashriq | G13: No | H13: No | I13: Yes
A14: 62 | B14: الوسام | C14: Al Wasam | D14: East | E14: =VLOOKUP(C14, Sheet2!C:D, 2, FALSE) -> East | F14: Al Wasam | G14: No | H14: No | I14: Yes
A15: 63 | B15: السحاب | C15: Al Sahab | D15: East | E15: =VLOOKUP(C15, Sheet2!C:D, 2, FALSE) -> East | F15: Al Sahab | G15: No | H15: No | I15: Yes
... A23: 151 | B23: مدينة الملك عبدالله للطاقة | C23: King Abdullah City For Energy | D23: West | E23: =VLOOKUP(C23, Sheet2!C:D, 2, FALSE) -> West | F23: King Abdullah City For Energy | G23: No | H23: No | I23: Yes
A24: 190 | B24: السهباء | C24: Asehbaa | D24: South | E24: =VLOOKUP(C24, Sheet2!C:D, 2, FALSE) -> South | F24: Asehbaa | G24: No | H24: No | I24: Yes | J24: A separate district but part of Al Haer
A25: 1 | B25: الفيصلية | C25: Al Faisaliyah | D25: Center | E25: =VLOOKUP(C25, Sheet2!C:D, 2, FALSE) -> Center | F25: Al Faisaliyah | G25: No | H25: Yes | I25: No
A26: 2 | B26: الصناعية | C26: Al Sinaiyah | D26: Center | E26: =VLOOKUP(C26, Sheet2!C:D, 2, FALSE) -> Center | F26: Al Sinaiyah | G26: No | H26: Yes | I26: No
A27: 3 | B27: الخالدية | C27: Al Khalidiyah | D27: Center | E27: =VLOOKUP(C27, Sheet2!C:D, 2, FALSE) -> Center | F27: Al Khalidiyah | G27: No | H27: Yes | I27: No
A28: 4 | B28: البطيحا | C28: Al Butaiha | D28: Center | E28: =VLOOKUP(C28, Sheet2!C:D, 2, FALSE) -> Center | F28: Al Butaiha | G28: No | H28: Yes | I28: No
A29: 49 | B29: الندوة | C29: Al Nadwah | D29: East | E29: =VLOOKUP(C29, Sheet2!C:D, 2, FALSE) -> East | F29: Al Nadwah | G29: No | H29: Yes | I29: No
A30: 100 | B30: سدرة | C30: Sedrah | D30: North | E30: =VLOOKUP(C30, Sheet2!C:D, 2, FALSE) -> East | F30: Sedrah | G30: No | H30: Yes | I30: No
A31: 101 | B31: مطار الملك خالد | C31: King Khalid International Airport | D31: North | E31: =VLOOKUP(C31, Sheet2!C:D, 2, FALSE) -> North | F31: King Khalid International Airport | G31: No | H31: Yes | I31: No | J31: Includes Dhahyat alkhuzam
A32: 144 | B32: الزهرة | C32: Al Zahrah | D32: West | E32: =VLOOKUP(C32, Sheet2!C:D, 2, FALSE) -> West | F32: Al Zahrah | G32: No | H32: Yes | I32: No
A33: 145 | B33: جامعة الملك سعود | C33: King Saud University | D33: West | E33: =VLOOKUP(C33, Sheet2!C:D, 2, FALSE) -> Center | F33: King Saud University | G33: No | H33: Yes | I33: No
A34: 146 | B34: ديراب | C34: Dirab | D34: West | E34: =VLOOKUP(C34, Sheet2!C:D, 2, FALSE) -> West | F34: Dirab | G34: No | H34: Yes | I34: No
A35: 147 | B35: طويق | C35: Tuwaiq | D35: West | E35: =VLOOKUP(C35, Sheet2!C:D, 2, FALSE) -> West | F35: Tuwaiq | G35: No | H35: Yes | I35: No
A36: 148 | B36: المهدية | C36: Al Mahdiyah | D36: West | E36: =VLOOKUP(C36, Sheet2!C:D, 2, FALSE) -> West | F36: Al Mahdiyah | G36: No | H36: Yes | I36: No
A37: 5 | B37: الازدهار | C37: Al Ezdihar | D37: Center | E37: =VLOOKUP(C37, Sheet2!C:D, 2, FALSE) -> Center | F37: Al Ezdihar | G37: Yes
A38: 6 | B38: التعاون | C38: Al Taawun | D38: Center | E38: =VLOOKUP(C38, Sheet2!C:D, 2, FALSE) -> Center | F38: Al Taawun | G38: Yes
A39: 7 | B39: المصيف | C39: Al Maseef | D39: Center | E39: =VLOOKUP(C39, Sheet2!C:D, 2, FALSE) -> Center | F39: Al Maseef | G39: Yes
A40: 8 | B40: المروج | C40: Al Muruj | D40: Center | E40: =VLOOKUP(C40, Sheet2!C:D, 2, FALSE) -> Center | F40: Al Muruj | G40: Yes
A41: 9 | B41: المغرزات | C41: Al Mughrazat | D41: Center | E41: =VLOOKUP(C41, Sheet2!C:D, 2, FALSE) -> Center | F41: Al Mughrazat | G41: Yes
A42: 10 | B42: النزهة | C42: Al Nuzha | D42: Center | E42: =VLOOKUP(C42, Sheet2!C:D, 2, FALSE) -> Center | F42: Al Nuzha | G42: Yes
A43: 11 | B43: المرسلات | C43: Al Mursalat | D43: Center | E43: =VLOOKUP(C43, Sheet2!C:D, 2, FALSE) -> Center | F43: Al Mursalat | G43: Yes
A44: 12 | B44: الملك فهد | C44: King Fahd | D44: Center | E44: =VLOOKUP(C44, Sheet2!C:D, 2, FALSE) -> Center | F44: King Fahd | G44: Yes
A45: 13 | B45: الملك عبدالله | C45: King Abdullah | D45: Center | E45: =VLOOKUP(C45, Sheet2!C:D, 2, FALSE) -> Center | F45: King Abdullah | G45: Yes
A46: 14 | B46: الملك سلمان | C46: King Salman | D46: Center | E46: =VLOOKUP(C46, Sheet2!C:D, 2, FALSE) -> Center | F46: King Salman | G46: Yes | J46: Al Wahah and Salahuddin previously
A47: 15 | B47: الورود | C47: Al Woroud | D47: Center | E47: =VLOOKUP(C47, Sheet2!C:D, 2, FALSE) -> Center | F47: Al Woroud | G47: Yes
...

Sheet Sheet2
A1: Number | B1: District Name in Arabic | C1: District Name in English | D1: New Region | E1: Done (Yes or No) | F1: Need to be checked (Yes or No) | G1: Empty based on google map (Yes or No) | H1: Comments | I1: Population
A2: 1 | B2: الازدهار | C2: Al Ezdihar | D2: Center | E2: Yes | I2: 35507
A3: 2 | B3: التعاون | C3: Al Taawun | D3: Center | E3: Yes | I3: 49965
A4: 3 | B4: المصيف | C4: Al Maseef | D4: Center | E4: Yes | I4: 42594
A5: 4 | B5: المروج | C5: Al Muruj | D5: Center | E5: Yes | I5: 39391
A6: 5 | B6: المغرزات | C6: Al Mughrazat | D6: Center | E6: Yes | I6: 16460
A7: 6 | B7: النزهة | C7: Al Nuzha | D7: Center | E7: Yes | I7: 27415
A8: 7 | B8: المرسلات | C8: Al Mursalat | D8: Center | E8: Yes | I8: 20338
A9: 8 | B9: الملك فهد | C9: King Fahd | D9: Center | E9: Yes | I9: 34511
A10: 9 | B10: الملك عبدالله | C10: King Abdullah | D10: Center | E10: Yes | I10: 17697
A11: 10 | B11: الملك سلمان | C11: King Salman | D11: Center | E11: Yes | H11: Al Wahah and Salahuddin previously | I11: 26336
A12: 11 | B12: الورود | C12: Al Woroud | D12: Center | E12: Yes | I12: 39241
A13: 12 | B13: الملك عبدالعزيز | C13: King Abdulaziz | D13: Center | E13: Yes | I13: 55187
A14: 13 | B14: السليمانية | C14: Al Sulaimaniyah | D14: Center | E14: Yes | I14: 90252
A15: 14 | B15: العليا | C15: Al Olaya | D15: Center | E15: Yes | I15: 118753
A16: 15 | B16: الربوة | C16: Ar Rabwah | D16: Center | E16: Yes | I16: 70591
A17: 16 | B17: الزهراء | C17: Al Zahra | D17: Center | E17: Yes | I17: 18684
A18: 17 | B18: الملز | C18: Al Malaz | D18: Center | E18: Yes | I18: 93066
A19: 18 | B19: الوزارات | C19: Al Wizarat | D19: Center | E19: Yes | I19: 65790
A20: 19 | B20: جرير | C20: Jareer | D20: Center | E20: Yes | I20: 30972
A21: 20 | B21: المربع | C21: Al Murabba | D21: Center | E21: Yes | I21: 58068
A22: 21 | B22: الفوطة | C22: Al Futah | D22: Center | E22: Yes | I22: 15526
A23: 22 | B23: العمل | C23: Al Amal | D23: Center | E23: Yes | I23: 20513
... A94: 156 | B94: الندوة | C94: Al Nadwah | D94: East | E94: Yes | I94: 43383
A95: 158 | B95: البساتين | C95: Al Basatin | D95: East | E95: Yes | H95: Includes Dhahyat Al Fursan | I95: 0
A96: 78 | B96: الفلاح | C96: Al Falah | D96: North | E96: Yes | I96: 24782
A97: 79 | B97: النفل | C97: Al Nafel | D97: North | E97: Yes | I97: 49438
A98: 80 | B98: الغدير | C98: Al Ghadeer | D98: North | E98: Yes | I98: 21308
A99: 81 | B99: العقيق | C99: Al Aqeeq | D99: North | E99: Yes | I99: 53471
A100: 82 | B100: حطين | C100: Hiteen | D100: North | E100: Yes | I100: 35795
A101: 83 | B101: الملقا | C101: Al Malqa | D101: North | E101: Yes | I101: 87931
A102: 84 | B102: الصحافة | C102: Al Sahafah | D102: North | E102: Yes | I102: 52135
A103: 85 | B103: الربيع | C103: Ar Rabie | D103: North | E103: Yes | I103: 35054
A104: 86 | B104: الندى | C104: Al Nada | D104: North | E104: Yes | I104: 19017
A105: 87 | B105: الياسمين | C105: Al Yasmeen | D105: North | E105: Yes | I105: 107229
A106: 88 | B106: جامعة الامام محمد بن سعود الاسلامية | C106: Imam Muhammed Bin Saud Islamic University | D106: North | E106: Yes | I106: 6241
A107: 89 | B107: النرجس | C107: Al Narjis | D107: North | E107: Yes | I107: 82800
... A113: 184 | B113: سدرة | C113: Sedrah | D113: East | E113: Yes | I113: 0
A114: 185 | B114: مطار الملك خالد | C114: King Khalid International Airport | D114: North | E114: Yes | H114: Includes Dhahyat Al Khuzam | I114: 17031
A115: 53 | B115: النسيم الشرقي | C115: East Naseem | D115: South | E115: Yes | I115: 139943
...
